Workbook

Sheet 장로 1차 선거 개표 집계표
A1: 2023년 장로 1차 선거 개표 집계표
A3: ⊙ 투표일자 : | B3: 2023 년 05 월 21 일 | E3: 작성자 | F3: 확인자 | G3: 감수자
A4: ⊙ 총투표자 : | B4: =조별합계표!F63 -> 409 | C4: 명
A5: ⊙ 무효표수 : | B5: =조별합계표!F62 -> 0 | C5: 명
A6: ⊙ 유효투표 : | B6: =조별합계표!F61 -> 0 | C6: 명
A7: ⊙ 개표시간 : | B7: 16:00 ~ 18:00
A8: ⊙ 작성일자 : | B8: 2023 년 05 월 21 일, 오후 4:00
A10: 연번 | B10: 이 름 | C10: 총투표수 | D10: 득표수 | E10: 득표율 | F10: 득표순위 | G10: 당선여부 | L10: 득표순위 | M10: 이 름 | N10: 총투표수 | O10: 득표수 | P10: 득표율 | Q10: 당선여부
A11: 1 | B11: =VLOOKUP(ROW(A1), L$11:Q$60, 2, FALSE) -> 정용석 | C11: =VLOOKUP(ROW(A1), L$11:Q$60, 3, FALSE) -> 409 | D11: =VLOOKUP(ROW(A1), L$11:Q$60, 4, FALSE) -> 198 | E11: =VLOOKUP(ROW(A1), L$11:Q$60, 5, FALSE) -> 0.48410758 | F11: =VLOOKUP(ROW(A1), L$11:Q$60, 1, FALSE) -> 1 | G11: =IF(E11>=0.666,"당선","-") -> - | L11: =RANK(P11,$P$11:$P$60) -> 12 | M11: =조별합계표!B4 -> 문동학 | N11: =$B$4 -> 409 | O11: =조별합계표!F4 -> 21 | P11: =O11/N11 -> 0.051344743 | Q11: =IF(P11>=0.666,"당선","-") -> -
A12: 2 | B12: =VLOOKUP(ROW(A2), L$11:Q$60, 2, FALSE) -> 반재수 | C12: =VLOOKUP(ROW(A2), L$11:Q$60, 3, FALSE) -> 409 | D12: =VLOOKUP(ROW(A2), L$11:Q$60, 4, FALSE) -> 191 | E12: =VLOOKUP(ROW(A2), L$11:Q$60, 5, FALSE) -> 0.46699267 | F12: =VLOOKUP(ROW(A2), L$11:Q$60, 1, FALSE) -> 2 | G12: =IF(E12>=0.666,"당선","-") -> - | L12: =RANK(P12,$P$11:$P$60) -> 21 | M12: =조별합계표!B5 -> 이주이 | N12: =$B$4 -> 409 | O12: =조별합계표!F5 -> 4 | P12: =O12/N12 -> 0.0097799511 | Q12: =IF(P12>=0.666,"당선","-") -> -
A13: 3 | B13: =VLOOKUP(ROW(A3), L$11:Q$60, 2, FALSE) -> 권오성 | C13: =VLOOKUP(ROW(A3), L$11:Q$60, 3, FALSE) -> 409 | D13: =VLOOKUP(ROW(A3), L$11:Q$60, 4, FALSE) -> 187 | E13: =VLOOKUP(ROW(A3), L$11:Q$60, 5, FALSE) -> 0.45721271 | F13: =VLOOKUP(ROW(A3), L$11:Q$60, 1, FALSE) -> 3 | G13: =IF(E13>=0.666,"당선","-") -> - | L13: =RANK(P13,$P$11:$P$60) -> 10 | M13: =조별합계표!B6 -> 이종수 | N13: =$B$4 -> 409 | O13: =조별합계표!F6 -> 26 | P13: =O13/N13 -> 0.063569682 | Q13: =IF(P13>=0.666,"당선","-") -> -
A14: 4 | B14: =VLOOKUP(ROW(A4), L$11:Q$60, 2, FALSE) -> 조규현 | C14: =VLOOKUP(ROW(A4), L$11:Q$60, 3, FALSE) -> 409 | D14: =VLOOKUP(ROW(A4), L$11:Q$60, 4, FALSE) -> 95 | E14: =VLOOKUP(ROW(A4), L$11:Q$60, 5, FALSE) -> 0.23227384 | F14: =VLOOKUP(ROW(A4), L$11:Q$60, 1, FALSE) -> 4 | G14: =IF(E14>=0.666,"당선","-") -> - | L14: =RANK(P14,$P$11:$P$60) -> 21 | M14: =조별합계표!B7 -> 조근배 | N14: =$B$4 -> 409 | O14: =조별합계표!F7 -> 4 | P14: =O14/N14 -> 0.0097799511 | Q14: =IF(P14>=0.666,"당선","-") -> -
A15: 5 | B15: =VLOOKUP(ROW(A5), L$11:Q$60, 2, FALSE) -> 김희정 | C15: =VLOOKUP(ROW(A5), L$11:Q$60, 3, FALSE) -> 409 | D15: =VLOOKUP(ROW(A5), L$11:Q$60, 4, FALSE) -> 83 | E15: =VLOOKUP(ROW(A5), L$11:Q$60, 5, FALSE) -> 0.20293399 | F15: =VLOOKUP(ROW(A5), L$11:Q$60, 1, FALSE) -> 5 | G15: =IF(E15>=0.666,"당선","-") -> - | L15: =RANK(P15,$P$11:$P$60) -> 20 | M15: =조별합계표!B8 -> 심효섭 | N15: =$B$4 -> 409 | O15: =조별합계표!F8 -> 5 | P15: =O15/N15 -> 0.012224939 | Q15: =IF(P15>=0.666,"당선","-") -> -
A16: 6 | B16: =VLOOKUP(ROW(A6), L$11:Q$60, 2, FALSE) -> 원종철 | C16: =VLOOKUP(ROW(A6), L$11:Q$60, 3, FALSE) -> 409 | D16: =VLOOKUP(ROW(A6), L$11:Q$60, 4, FALSE) -> 79 | E16: =VLOOKUP(ROW(A6), L$11:Q$60, 5, FALSE) -> 0.19315403 | F16: =VLOOKUP(ROW(A6), L$11:Q$60, 1, FALSE) -> 6 | G16: =IF(E16>=0.666,"당선","-") -> - | L16: =RANK(P16,$P$11:$P$60) -> 19 | M16: =조별합계표!B9 -> 이강우 | N16: =$B$4 -> 409 | O16: =조별합계표!F9 -> 8 | P16: =O16/N16 -> 0.019559902 | Q16: =IF(P16>=0.666,"당선","-") -> -
A17: 7 | B17: =VLOOKUP(ROW(A7), L$11:Q$60, 2, FALSE) -> 이준호 | C17: =VLOOKUP(ROW(A7), L$11:Q$60, 3, FALSE) -> 409 | D17: =VLOOKUP(ROW(A7), L$11:Q$60, 4, FALSE) -> 73 | E17: =VLOOKUP(ROW(A7), L$11:Q$60, 5, FALSE) -> 0.17848411 | F17: =VLOOKUP(ROW(A7), L$11:Q$60, 1, FALSE) -> 7 | G17: =IF(E17>=0.666,"당선","-") -> - | L17: =RANK(P17,$P$11:$P$60) -> 2 | M17: =조별합계표!B10 -> 반재수 | N17: =$B$4 -> 409 | O17: =조별합계표!F10 -> 191 | P17: =O17/N17 -> 0.46699267 | Q17: =IF(P17>=0.666,"당선","-") -> -
A18: 8 | B18: =VLOOKUP(ROW(A8), L$11:Q$60, 2, FALSE) -> 이현준 | C18: =VLOOKUP(ROW(A8), L$11:Q$60, 3, FALSE) -> 409 | D18: =VLOOKUP(ROW(A8), L$11:Q$60, 4, FALSE) -> 38 | E18: =VLOOKUP(ROW(A8), L$11:Q$60, 5, FALSE) -> 0.092909535 | F18: =VLOOKUP(ROW(A8), L$11:Q$60, 1, FALSE) -> 8 | G18: =IF(E18>=0.666,"당선","-") -> - | L18: =RANK(P18,$P$11:$P$60) -> 21 | M18: =조별합계표!B11 -> 장태익 | N18: =$B$4 -> 409 | O18: =조별합계표!F11 -> 4 | P18: =O18/N18 -> 0.0097799511 | Q18: =IF(P18>=0.666,"당선","-") -> -
A19: 9 | B19: =VLOOKUP(ROW(A9), L$11:Q$60, 2, FALSE) -> 백운재 | C19: =VLOOKUP(ROW(A9), L$11:Q$60, 3, FALSE) -> 409 | D19: =VLOOKUP(ROW(A9), L$11:Q$60, 4, FALSE) -> 37 | E19: =VLOOKUP(ROW(A9), L$11:Q$60, 5, FALSE) -> 0.090464548 | F19: =VLOOKUP(ROW(A9), L$11:Q$60, 1, FALSE) -> 9 | G19: =IF(E19>=0.666,"당선","-") -> - | L19: =RANK(P19,$P$11:$P$60) -> 1 | M19: =조별합계표!B12 -> 정용석 | N19: =$B$4 -> 409 | O19: =조별합계표!F12 -> 198 | P19: =O19/N19 -> 0.48410758 | Q19: =IF(P19>=0.666,"당선","-") -> -
A20: 10 | B20: =VLOOKUP(ROW(A10), L$11:Q$60, 2, FALSE) -> 이종수 | C20: =VLOOKUP(ROW(A10), L$11:Q$60, 3, FALSE) -> 409 | D20: =VLOOKUP(ROW(A10), L$11:Q$60, 4, FALSE) -> 26 | E20: =VLOOKUP(ROW(A10), L$11:Q$60, 5, FALSE) -> 0.063569682 | F20: =VLOOKUP(ROW(A10), L$11:Q$60, 1, FALSE) -> 10 | G20: =IF(E20>=0.666,"당선","-") -> - | L20: =RANK(P20,$P$11:$P$60) -> 25 | M20: =조별합계표!B13 -> 유양준 | N20: =$B$4 -> 409 | O20: =조별합계표!F13 -> 3 | P20: =O20/N20 -> 0.0073349633 | Q20: =IF(P20>=0.666,"당선","-") -> -
A21: 11 | B21: =VLOOKUP(ROW(A11), L$11:Q$60, 2, FALSE) -> #N/A | C21: =VLOOKUP(ROW(A11), L$11:Q$60, 3, FALSE) -> #N/A | D21: =VLOOKUP(ROW(A11), L$11:Q$60, 4, FALSE) -> #N/A | E21: =VLOOKUP(ROW(A11), L$11:Q$60, 5, FALSE) -> #N/A | F21: =VLOOKUP(ROW(A11), L$11:Q$60, 1, FALSE) -> #N/A | G21: =IF(E21>=0.666,"당선","-") -> #N/A | H21: 문용오 | L21: =RANK(P21,$P$11:$P$60) -> 34 | M21: =조별합계표!B14 -> 황영수 | N21: =$B$4 -> 409 | O21: =조별합계표!F14 -> 1 | P21: =O21/N21 -> 0.0024449878 | Q21: =IF(P21>=0.666,"당선","-") -> -
A22: 12 | B22: =VLOOKUP(ROW(A12), L$11:Q$60, 2, FALSE) -> 문동학 | C22: =VLOOKUP(ROW(A12), L$11:Q$60, 3, FALSE) -> 409 | D22: =VLOOKUP(ROW(A12), L$11:Q$60, 4, FALSE) -> 21 | E22: =VLOOKUP(ROW(A12), L$11:Q$60, 5, FALSE) -> 0.051344743 | F22: =VLOOKUP(ROW(A12), L$11:Q$60, 1, FALSE) -> 12 | G22: =IF(E22>=0.666,"당선","-") -> - | L22: =RANK(P22,$P$11:$P$60) -> 6 | M22: =조별합계표!B15 -> 원종철 | N22: =$B$4 -> 409 | O22: =조별합계표!F15 -> 79 | P22: =O22/N22 -> 0.19315403 | Q22: =IF(P22>=0.666,"당선","-") -> -
A23: 13 | B23: =VLOOKUP(ROW(A13), L$11:Q$60, 2, FALSE) -> 이규현 | C23: =VLOOKUP(ROW(A13), L$11:Q$60, 3, FALSE) -> 409 | D23: =VLOOKUP(ROW(A13), L$11:Q$60, 4, FALSE) -> 20 | E23: =VLOOKUP(ROW(A13), L$11:Q$60, 5, FALSE) -> 0.048899756 | F23: =VLOOKUP(ROW(A13), L$11:Q$60, 1, FALSE) -> 13 | G23: =IF(E23>=0.666,"당선","-") -> - | L23: =RANK(P23,$P$11:$P$60) -> 25 | M23: =조별합계표!B16 -> 진인식 | N23: =$B$4 -> 409 | O23: =조별합계표!F16 -> 3 | P23: =O23/N23 -> 0.0073349633 | Q23: =IF(P23>=0.666,"당선","-") -> -
A24: 14 | B24: =VLOOKUP(ROW(A14), L$11:Q$60, 2, FALSE) -> 김관형 | C24: =VLOOKUP(ROW(A14), L$11:Q$60, 3, FALSE) -> 409 | D24: =VLOOKUP(ROW(A14), L$11:Q$60, 4, FALSE) -> 19 | E24: =VLOOKUP(ROW(A14), L$11:Q$60, 5, FALSE) -> 0.046454768 | F24: =VLOOKUP(ROW(A14), L$11:Q$60, 1, FALSE) -> 14 | G24: =IF(E24>=0.666,"당선","-") -> - | L24: =RANK(P24,$P$11:$P$60) -> 5 | M24: =조별합계표!B17 -> 김희정 | N24: =$B$4 -> 409 | O24: =조별합계표!F17 -> 83 | P24: =O24/N24 -> 0.20293399 | Q24: =IF(P24>=0.666,"당선","-") -> -
A25: 15 | B25: =VLOOKUP(ROW(A15), L$11:Q$60, 2, FALSE) -> 안방선 | C25: =VLOOKUP(ROW(A15), L$11:Q$60, 3, FALSE) -> 409 | D25: =VLOOKUP(ROW(A15), L$11:Q$60, 4, FALSE) -> 15 | E25: =VLOOKUP(ROW(A15), L$11:Q$60, 5, FALSE) -> 0.036674817 | F25: =VLOOKUP(ROW(A15), L$11:Q$60, 1, FALSE) -> 15 | G25: =IF(E25>=0.666,"당선","-") -> - | L25: =RANK(P25,$P$11:$P$60) -> 14 | M25: =조별합계표!B18 -> 김관형 | N25: =$B$4 -> 409 | O25: =조별합계표!F18 -> 19 | P25: =O25/N25 -> 0.046454768 | Q25: =IF(P25>=0.666,"당선","-") -> -
A26: 16 | B26: =VLOOKUP(ROW(A16), L$11:Q$60, 2, FALSE) -> 김태성 | C26: =VLOOKUP(ROW(A16), L$11:Q$60, 3, FALSE) -> 409 | D26: =VLOOKUP(ROW(A16), L$11:Q$60, 4, FALSE) -> 14 | E26: =VLOOKUP(ROW(A16), L$11:Q$60, 5, FALSE) -> 0.034229829 | F26: =VLOOKUP(ROW(A16), L$11:Q$60, 1, FALSE) -> 16 | G26: =IF(E26>=0.666,"당선","-") -> - | L26: =RANK(P26,$P$11:$P$60) -> 17 | M26: =조별합계표!B19 -> 김남영 | N26: =$B$4 -> 409 | O26: =조별합계표!F19 -> 10 | P26: =O26/N26 -> 0.024449878 | Q26: =IF(P26>=0.666,"당선","-") -> -
A27: 17 | B27: =VLOOKUP(ROW(A17), L$11:Q$60, 2, FALSE) -> 김남영 | C27: =VLOOKUP(ROW(A17), L$11:Q$60, 3, FALSE) -> 409 | D27: =VLOOKUP(ROW(A17), L$11:Q$60, 4, FALSE) -> 10 | E27: =VLOOKUP(ROW(A17), L$11:Q$60, 5, FALSE) -> 0.024449878 | F27: =VLOOKUP(ROW(A17), L$11:Q$60, 1, FALSE) -> 17 | G27: =IF(E27>=0.666,"당선","-") -> - | L27: =RANK(P27,$P$11:$P$60) -> 4 | M27: =조별합계표!B20 -> 조규현 | N27: =$B$4 -> 409 | O27: =조별합계표!F20 -> 95 | P27: =O27/N27 -> 0.23227384 | Q27: =IF(P27>=0.666,"당선","-") -> -
A28: 18 | B28: =VLOOKUP(ROW(A18), L$11:Q$60, 2, FALSE) -> #N/A | C28: =VLOOKUP(ROW(A18), L$11:Q$60, 3, FALSE) -> #N/A | D28: =VLOOKUP(ROW(A18), L$11:Q$60, 4, FALSE) -> #N/A | E28: =VLOOKUP(ROW(A18), L$11:Q$60, 5, FALSE) -> #N/A | F28: =VLOOKUP(ROW(A18), L$11:Q$60, 1, FALSE) -> #N/A | G28: =IF(E28>=0.666,"당선","-") -> #N/A | H28: 정보람 | L28: =RANK(P28,$P$11:$P$60) -> 30 | M28: =조별합계표!B21 -> 최영철 | N28: =$B$4 -> 409 | O28: =조별합계표!F21 -> 2 | P28: =O28/N28 -> 0.0048899756 | Q28: =IF(P28>=0.666,"당선","-") -> -
A29: 19 | B29: =VLOOKUP(ROW(A19), L$11:Q$60, 2, FALSE) -> 이강우 | C29: =VLOOKUP(ROW(A19), L$11:Q$60, 3, FALSE) -> 409 | D29: =VLOOKUP(ROW(A19), L$11:Q$60, 4, FALSE) -> 8 | E29: =VLOOKUP(ROW(A19), L$11:Q$60, 5, FALSE) -> 0.019559902 | F29: =VLOOKUP(ROW(A19), L$11:Q$60, 1, FALSE) -> 19 | G29: =IF(E29>=0.666,"당선","-") -> - | L29: =RANK(P29,$P$11:$P$60) -> 39 | M29: =조별합계표!B22 -> 최인석 | N29: =$B$4 -> 409 | O29: =조별합계표!F22 -> 0 | P29: =O29/N29 -> 0 | Q29: =IF(P29>=0.666,"당선","-") -> -
A30: 20 | B30: =VLOOKUP(ROW(A20), L$11:Q$60, 2, FALSE) -> 심효섭 | C30: =VLOOKUP(ROW(A20), L$11:Q$60, 3, FALSE) -> 409 | D30: =VLOOKUP(ROW(A20), L$11:Q$60, 4, FALSE) -> 5 | E30: =VLOOKUP(ROW(A20), L$11:Q$60, 5, FALSE) -> 0.012224939 | F30: =VLOOKUP(ROW(A20), L$11:Q$60, 1, FALSE) -> 20 | G30: =IF(E30>=0.666,"당선","-") -> - | L30: =RANK(P30,$P$11:$P$60) -> 9 | M30: =조별합계표!B23 -> 백운재 | N30: =$B$4 -> 409 | O30: =조별합계표!F23 -> 37 | P30: =O30/N30 -> 0.090464548 | Q30: =IF(P30>=0.666,"당선","-") -> -
A31: 21 | B31: =VLOOKUP(ROW(A21), L$11:Q$60, 2, FALSE) -> 이주이 | C31: =VLOOKUP(ROW(A21), L$11:Q$60, 3, FALSE) -> 409 | D31: =VLOOKUP(ROW(A21), L$11:Q$60, 4, FALSE) -> 4 | E31: =VLOOKUP(ROW(A21), L$11:Q$60, 5, FALSE) -> 0.0097799511 | F31: =VLOOKUP(ROW(A21), L$11:Q$60, 1, FALSE) -> 21 | G31: =IF(E31>=0.666,"당선","-") -> - | L31: =RANK(P31,$P$11:$P$60) -> 39 | M31: =조별합계표!B24 -> 최광호 | N31: =$B$4 -> 409 | O31: =조별합계표!F24 -> 0 | P31: =O31/N31 -> 0 | Q31: =IF(P31>=0.666,"당선","-") -> -
A32: 22 | B32: =VLOOKUP(ROW(A22), L$11:Q$60, 2, FALSE) -> #N/A | C32: =VLOOKUP(ROW(A22), L$11:Q$60, 3, FALSE) -> #N/A | D32: =VLOOKUP(ROW(A22), L$11:Q$60, 4, FALSE) -> #N/A | E32: =VLOOKUP(ROW(A22), L$11:Q$60, 5, FALSE) -> #N/A | F32: =VLOOKUP(ROW(A22), L$11:Q$60, 1, FALSE) -> #N/A | G32: =IF(E32>=0.666,"당선","-") -> #N/A | L32: =RANK(P32,$P$11:$P$60) -> 34 | M32: =조별합계표!B25 -> 윤진 | N32: =$B$4 -> 409 | O32: =조별합계표!F25 -> 1 | P32: =O32/N32 -> 0.0024449878 | Q32: =IF(P32>=0.666,"당선","-") -> -
A33: 23 | B33: =VLOOKUP(ROW(A23), L$11:Q$60, 2, FALSE) -> #N/A | C33: =VLOOKUP(ROW(A23), L$11:Q$60, 3, FALSE) -> #N/A | D33: =VLOOKUP(ROW(A23), L$11:Q$60, 4, FALSE) -> #N/A | E33: =VLOOKUP(ROW(A23), L$11:Q$60, 5, FALSE) -> #N/A | F33: =VLOOKUP(ROW(A23), L$11:Q$60, 1, FALSE) -> #N/A | G33: =IF(E33>=0.666,"당선","-") -> #N/A | L33: =RANK(P33,$P$11:$P$60) -> 7 | M33: =조별합계표!B26 -> 이준호 | N33: =$B$4 -> 409 | O33: =조별합계표!F26 -> 73 | P33: =O33/N33 -> 0.17848411 | Q33: =IF(P33>=0.666,"당선","-") -> -
A34: 24 | B34: =VLOOKUP(ROW(A24), L$11:Q$60, 2, FALSE) -> #N/A | C34: =VLOOKUP(ROW(A24), L$11:Q$60, 3, FALSE) -> #N/A | D34: =VLOOKUP(ROW(A24), L$11:Q$60, 4, FALSE) -> #N/A | E34: =VLOOKUP(ROW(A24), L$11:Q$60, 5, FALSE) -> #N/A | F34: =VLOOKUP(ROW(A24), L$11:Q$60, 1, FALSE) -> #N/A | G34: =IF(E34>=0.666,"당선","-") -> #N/A | L34: =RANK(P34,$P$11:$P$60) -> 16 | M34: =조별합계표!B27 -> 김태성 | N34: =$B$4 -> 409 | O34: =조별합계표!F27 -> 14 | P34: =O34/N34 -> 0.034229829 | Q34: =IF(P34>=0.666,"당선","-") -> -
A35: 25 | B35: =VLOOKUP(ROW(A25), L$11:Q$60, 2, FALSE) -> 유양준 | C35: =VLOOKUP(ROW(A25), L$11:Q$60, 3, FALSE) -> 409 | D35: =VLOOKUP(ROW(A25), L$11:Q$60, 4, FALSE) -> 3 | E35: =VLOOKUP(ROW(A25), L$11:Q$60, 5, FALSE) -> 0.0073349633 | F35: =VLOOKUP(ROW(A25), L$11:Q$60, 1, FALSE) -> 25 | G35: =IF(E35>=0.666,"당선","-") -> - | L35: =RANK(P35,$P$11:$P$60) -> 13 | M35: =조별합계표!B28 -> 이규현 | N35: =$B$4 -> 409 | O35: =조별합계표!F28 -> 20 | P35: =O35/N35 -> 0.048899756 | Q35: =IF(P35>=0.666,"당선","-") -> -
A36: 26 | B36: =VLOOKUP(ROW(A26), L$11:Q$60, 2, FALSE) -> #N/A | C36: =VLOOKUP(ROW(A26), L$11:Q$60, 3, FALSE) -> #N/A | D36: =VLOOKUP(ROW(A26), L$11:Q$60, 4, FALSE) -> #N/A | E36: =VLOOKUP(ROW(A26), L$11:Q$60, 5, FALSE) -> #N/A | F36: =VLOOKUP(ROW(A26), L$11:Q$60, 1, FALSE) -> #N/A | G36: =IF(E36>=0.666,"당선","-") -> #N/A | L36: =RANK(P36,$P$11:$P$60) -> 8 | M36: =조별합계표!B29 -> 이현준 | N36: =$B$4 -> 409 | O36: =조별합계표!F29 -> 38 | P36: =O36/N36 -> 0.092909535 | Q36: =IF(P36>=0.666,"당선","-") -> -
A37: 27 | B37: =VLOOKUP(ROW(A27), L$11:Q$60, 2, FALSE) -> #N/A | C37: =VLOOKUP(ROW(A27), L$11:Q$60, 3, FALSE) -> #N/A | D37: =VLOOKUP(ROW(A27), L$11:Q$60, 4, FALSE) -> #N/A | E37: =VLOOKUP(ROW(A27), L$11:Q$60, 5, FALSE) -> #N/A | F37: =VLOOKUP(ROW(A27), L$11:Q$60, 1, FALSE) -> #N/A | G37: =IF(E37>=0.666,"당선","-") -> #N/A | L37: =RANK(P37,$P$11:$P$60) -> 39 | M37: =조별합계표!B30 -> 김홍균 | N37: =$B$4 -> 409 | O37: =조별합계표!F30 -> 0 | P37: =O37/N37 -> 0 | Q37: =IF(P37>=0.666,"당선","-") -> -
A38: 28 | B38: =VLOOKUP(ROW(A28), L$11:Q$60, 2, FALSE) -> #N/A | C38: =VLOOKUP(ROW(A28), L$11:Q$60, 3, FALSE) -> #N/A | D38: =VLOOKUP(ROW(A28), L$11:Q$60, 4, FALSE) -> #N/A | E38: =VLOOKUP(ROW(A28), L$11:Q$60, 5, FALSE) -> #N/A | F38: =VLOOKUP(ROW(A28), L$11:Q$60, 1, FALSE) -> #N/A | G38: =IF(E38>=0.666,"당선","-") -> #N/A | L38: =RANK(P38,$P$11:$P$60) -> 39 | M38: =조별합계표!B31 -> 강지원 | N38: =$B$4 -> 409 | O38: =조별합계표!F31 -> 0 | P38: =O38/N38 -> 0 | Q38: =IF(P38>=0.666,"당선","-") -> -
A39: 29 | B39: =VLOOKUP(ROW(A29), L$11:Q$60, 2, FALSE) -> #N/A | C39: =VLOOKUP(ROW(A29), L$11:Q$60, 3, FALSE) -> #N/A | D39: =VLOOKUP(ROW(A29), L$11:Q$60, 4, FALSE) -> #N/A | E39: =VLOOKUP(ROW(A29), L$11:Q$60, 5, FALSE) -> #N/A | F39: =VLOOKUP(ROW(A29), L$11:Q$60, 1, FALSE) -> #N/A | G39: =IF(E39>=0.666,"당선","-") -> #N/A | L39: =RANK(P39,$P$11:$P$60) -> 21 | M39: =조별합계표!B32 -> 손성길 | N39: =$B$4 -> 409 | O39: =조별합계표!F32 -> 4 | P39: =O39/N39 -> 0.0097799511 | Q39: =IF(P39>=0.666,"당선","-") -> -
A40: 30 | B40: =VLOOKUP(ROW(A30), L$11:Q$60, 2, FALSE) -> 최영철 | C40: =VLOOKUP(ROW(A30), L$11:Q$60, 3, FALSE) -> 409 | D40: =VLOOKUP(ROW(A30), L$11:Q$60, 4, FALSE) -> 2 | E40: =VLOOKUP(ROW(A30), L$11:Q$60, 5, FALSE) -> 0.0048899756 | F40: =VLOOKUP(ROW(A30), L$11:Q$60, 1, FALSE) -> 30 | G40: =IF(E40>=0.666,"당선","-") -> - | L40: =RANK(P40,$P$11:$P$60) -> 39 | M40: =조별합계표!B33 -> 김홍철 | N40: =$B$4 -> 409 | O40: =조별합계표!F33 -> 0 | P40: =O40/N40 -> 0 | Q40: =IF(P40>=0.666,"당선","-") -> -
... A60: 50 | B60: =VLOOKUP(ROW(A50), L$11:Q$60, 2, FALSE) -> #N/A | C60: =VLOOKUP(ROW(A50), L$11:Q$60, 3, FALSE) -> #N/A | D60: =VLOOKUP(ROW(A50), L$11:Q$60, 4, FALSE) -> #N/A | E60: =VLOOKUP(ROW(A50), L$11:Q$60, 5, FALSE) -> #N/A | F60: =VLOOKUP(ROW(A50), L$11:Q$60, 1, FALSE) -> #N/A | G60: =IF(E60>=0.666,"당선","-") -> #N/A | L60: =RANK(P60,$P$11:$P$60) -> 30 | M60: =조별합계표!B53 -> 0 | N60: =$B$4 -> 409 | O60: =조별합계표!F53 -> 2 | P60: =O60/N60 -> 0.0048899756 | Q60: =IF(P60>=0.666,"당선","-") -> -

Sheet 조별합계표
A1: 2023년 양평동교회 항존직 1차 선거 개표 집계표 - 조별 합계표
A3: 기 호 | B3: 이 름 | C3: A조 | D3: B조 | E3: C조 | F3: 합계
A4: 1 | B4: 문동학 | C4: =개표집계표A!J5 -> 10 | D4: =개표집계표B!J5 -> 2 | E4: =개표집계표C!J5 -> 9 | F4: =SUM(C4:E4) -> 21
A5: 2 | B5: 이주이 | C5: =개표집계표A!J6 -> 1 | D5: =개표집계표B!J6 -> 2 | E5: =개표집계표C!J6 -> 1 | F5: =SUM(C5:E5) -> 4
A6: 3 | B6: 이종수 | C6: =개표집계표A!J7 -> 9 | D6: =개표집계표B!J7 -> 5 | E6: =개표집계표C!J7 -> 12 | F6: =SUM(C6:E6) -> 26
A7: 4 | B7: 조근배 | C7: =개표집계표A!J8 -> 1 | D7: =개표집계표B!J8 -> 1 | E7: =개표집계표C!J8 -> 2 | F7: =SUM(C7:E7) -> 4
A8: 5 | B8: 심효섭 | C8: =개표집계표A!J9 -> 3 | D8: =개표집계표B!J9 -> 0 | E8: =개표집계표C!J9 -> 2 | F8: =SUM(C8:E8) -> 5
A9: 6 | B9: 이강우 | C9: =개표집계표A!J10 -> 1 | D9: =개표집계표B!J10 -> 3 | E9: =개표집계표C!J10 -> 4 | F9: =SUM(C9:E9) -> 8
A10: 7 | B10: 반재수 | C10: =개표집계표A!J11 -> 46 | D10: =개표집계표B!J11 -> 75 | E10: =개표집계표C!J11 -> 70 | F10: =SUM(C10:E10) -> 191
A11: 8 | B11: 장태익 | C11: =개표집계표A!J12 -> 1 | D11: =개표집계표B!J12 -> 0 | E11: =개표집계표C!J12 -> 3 | F11: =SUM(C11:E11) -> 4
A12: 9 | B12: 정용석 | C12: =개표집계표A!J13 -> 53 | D12: =개표집계표B!J13 -> 70 | E12: =개표집계표C!J13 -> 75 | F12: =SUM(C12:E12) -> 198
A13: 10 | B13: 유양준 | C13: =개표집계표A!J14 -> 2 | D13: =개표집계표B!J14 -> 1 | E13: =개표집계표C!J14 -> 0 | F13: =SUM(C13:E13) -> 3
A14: 11 | B14: 황영수 | C14: =개표집계표A!J15 -> 0 | D14: =개표집계표B!J15 -> 0 | E14: =개표집계표C!J15 -> 1 | F14: =SUM(C14:E14) -> 1
A15: 12 | B15: 원종철 | C15: =개표집계표A!J16 -> 18 | D15: =개표집계표B!J16 -> 34 | E15: =개표집계표C!J16 -> 27 | F15: =SUM(C15:E15) -> 79
... A50: 47 | B50: 안방선 | C50: =개표집계표A!J51 -> 5 | D50: =개표집계표B!J51 -> 3 | E50: =개표집계표C!J51 -> 7 | F50: =SUM(C50:E50) -> 15
A51: 48 | C51: =개표집계표A!J52 -> 1 | D51: =개표집계표B!J52 -> 1 | E51: =개표집계표C!J52 -> 1 | F51: =SUM(C51:E51) -> 3
A52: 49 | C52: =개표집계표A!J53 -> 1 | D52: =개표집계표B!J53 -> 1 | E52: =개표집계표C!J53 -> 1 | F52: =SUM(C52:E52) -> 3
A53: 50 | C53: =개표집계표A!J54 -> 0 | D53: =개표집계표B!J54 -> 1 | E53: =개표집계표C!J54 -> 1 | F53: =SUM(C53:E53) -> 2
A54: 51 | C54: =개표집계표A!J55 -> 0 | D54: =개표집계표B!J55 -> 1 | E54: =개표집계표C!J55 -> 1 | F54: =SUM(C54:E54) -> 2
A55: 52 | C55: =개표집계표A!J56 -> 0 | D55: =개표집계표B!J56 -> 1 | E55: =개표집계표C!J56 -> 0 | F55: =SUM(C55:E55) -> 1
A56: 53 | F56: =SUM(C56:E56) -> 0
A57: 54 | F57: =SUM(C57:E57) -> 0
A58: 55 | F58: =SUM(C58:E58) -> 0
A59: 56 | F59: =SUM(C59:E59) -> 0
F60: =SUM(F4:F59) -> 1202
A61: 유효 투표수 | F61: =SUM(C61:E61) -> 0
A62: 무효 투표수 | C62: 0 | D62: 0 | E62: 0 | F62: =SUM(C62:E62) -> 0
A63: 총 투표자수 | C63: =개표집계표A!J67 -> 108 | D63: =개표집계표B!J67 -> 150 | E63: =개표집계표C!J67 -> 151 | F63: =SUM(C63:E63) -> 409

Sheet 개표집계표A
A1: 2023년 양평동교회 항존직 1차 선거 개표 집계표 - A조
E2: 개표자 : 남택정
A3: 연번 | B3: 일렬번호 | C3: 1 | D3: 2 | E3: 3 | F3: 비고 | H3: 후보합계
A4: 1 | B4: 174 | H4: 연번 | I4: 이름 | J4: 합계
A5: 2 | B5: 226 | H5: 1 | I5: 문동학 | J5: =COUNTIF(($C$4:$E$207),I5) -> 10
A6: 3 | B6: 261 | C6: 김관형 | D6: 김희정 | E6: 조규현 | H6: 2 | I6: 이주이 | J6: =COUNTIF(($C$4:$E$207),I6) -> 1
A7: 4 | B7: 121 | C7: 권오성 | D7: 조규현 | E7: 반재수 | H7: 3 | I7: 이종수 | J7: =COUNTIF(($C$4:$E$207),I7) -> 9
A8: 5 | B8: 64 | C8: 권오성 | D8: 정용석 | E8: 반재수 | H8: 4 | I8: 조근배 | J8: =COUNTIF(($C$4:$E$207),I8) -> 1
A9: 6 | B9: 47 | C9: 문동학 | D9: 반재수 | E9: 문용오 | H9: 5 | I9: 심효섭 | J9: =COUNTIF(($C$4:$E$207),I9) -> 3
A10: 7 | B10: 402 | C10: 문동학 | D10: 심효섭 | E10: 반재수 | H10: 6 | I10: 이강우 | J10: =COUNTIF(($C$4:$E$207),I10) -> 1
A11: 8 | B11: 124 | C11: 정용석 | D11: 반재수 | E11: 권오성 | H11: 7 | I11: 반재수 | J11: =COUNTIF(($C$4:$E$207),I11) -> 46
A12: 9 | B12: 49 | C12: 반재수 | D12: 이강우 | E12: 김관형 | H12: 8 | I12: 장태익 | J12: =COUNTIF(($C$4:$E$207),I12) -> 1
A13: 10 | B13: 53 | C13: 권오성 | D13: 정용석 | E13: 이준호 | H13: 9 | I13: 정용석 | J13: =COUNTIF(($C$4:$E$207),I13) -> 53
A14: 11 | B14: 242 | C14: 반재수 | D14: 문동학 | E14: 심효섭 | H14: 10 | I14: 유양준 | J14: =COUNTIF(($C$4:$E$207),I14) -> 2
A15: 12 | B15: 251 | C15: 백운재 | D15: 정용석 | E15: 반재수 | H15: 11 | I15: 황명수 | J15: =COUNTIF(($C$4:$E$207),I15) -> 0
A16: 13 | B16: 241 | C16: 반재수 | H16: 12 | I16: 원종철 | J16: =COUNTIF(($C$4:$E$207),I16) -> 18
A17: 14 | B17: 145 | C17: 정용석 | D17: 김희정 | E17: 조규현 | H17: 13 | I17: 진인식 | J17: =COUNTIF(($C$4:$E$207),I17) -> 0
A18: 15 | B18: 68 | C18: 조규현 | D18: 정용석 | E18: 김태성 | H18: 14 | I18: 김희정 | J18: =COUNTIF(($C$4:$E$207),I18) -> 19
A19: 16 | B19: 449 | C19: 문동학 | D19: 이주이 | E19: 이종수 | H19: 15 | I19: 김관형 | J19: =COUNTIF(($C$4:$E$207),I19) -> 6
A20: 17 | B20: 149 | C20: 정용석 | D20: 권오성 | E20: 이현준 | H20: 16 | I20: 김남영 | J20: =COUNTIF(($C$4:$E$207),I20) -> 4
A21: 18 | B21: 80 | C21: 권오성 | D21: 정용석 | E21: 조규현 | H21: 17 | I21: 조규현 | J21: =COUNTIF(($C$4:$E$207),I21) -> 30
A22: 19 | B22: 277 | C22: 정용석 | D22: 김태성 | E22: 조규현 | H22: 18 | I22: 최영철 | J22: =COUNTIF(($C$4:$E$207),I22) -> 0
A23: 20 | B23: 177 | C23: 권오성 | D23: 조규현 | E23: 이종수 | H23: 19 | I23: 최인석 | J23: =COUNTIF(($C$4:$E$207),I23) -> 0
A24: 21 | B24: 274 | C24: 문동학 | D24: 반재수 | E24: 정용석 | H24: 20 | I24: 백운재 | J24: =COUNTIF(($C$4:$E$207),I24) -> 8
A25: 22 | B25: 141 | C25: 정용석 | D25: 권오성 | E25: 반재수 | H25: 21 | I25: 최광호 | J25: =COUNTIF(($C$4:$E$207),I25) -> 0
A26: 23 | B26: 410 | C26: 정용석 | D26: 정보람 | E26: 강명구 | H26: 22 | I26: 윤진 | J26: =COUNTIF(($C$4:$E$207),I26) -> 0
A27: 24 | B27: 287 | C27: 김희정 | D27: 원종철 | E27: 조규현 | H27: 23 | I27: 이준호 | J27: =COUNTIF(($C$4:$E$207),I27) -> 16
A28: 25 | B28: 295 | C28: 정용석 | D28: 조규현 | E28: 김희정 | H28: 24 | I28: 김태성 | J28: =COUNTIF(($C$4:$E$207),I28) -> 3
... A45: 42 | B45: 419 | C45: 정용석 | D45: 반재수 | E45: 원종철 | H45: 41 | I45: 강동일 | J45: =COUNTIF(($C$4:$E$207),I45) -> 0
A46: 43 | B46: 41 | C46: 권오성 | D46: 반재수 | H46: 42 | I46: 손유재 | J46: =COUNTIF(($C$4:$E$207),I46) -> 0
A47: 44 | B47: 7 | C47: 반재수 | D47: 정용석 | E47: 권오성 | H47: 43 | I47: 박재환 | J47: =COUNTIF(($C$4:$E$207),I47) -> 0
A48: 45 | B48: 23 | C48: 권오성 | D48: 반재수 | E48: 원종철 | H48: 44 | I48: 강명구 | J48: =COUNTIF(($C$4:$E$207),I48) -> 1
A49: 46 | B49: 39 | C49: 반재수 | D49: 정용석 | E49: 이종수 | H49: 45 | I49: 김한경 | J49: =COUNTIF(($C$4:$E$207),I49) -> 0
A50: 47 | B50: 8 | C50: 정용석 | D50: 원종철 | E50: 김희정 | H50: 46 | I50: 백선일 | J50: =COUNTIF(($C$4:$E$207),I50) -> 0
A51: 48 | B51: 228 | C51: 이준호 | D51: 반재수 | E51: 김남영 | H51: 47 | I51: 안방선 | J51: =COUNTIF(($C$4:$E$207),I51) -> 5
A52: 49 | B52: 30 | C52: 정용석 | H52: 48 | I52: 김행숙 | J52: =COUNTIF(($C$4:$E$207),I52) -> 1 | L52: =SUM(J5:J52)+14 -> 323
A53: 50 | B53: 18 | C53: 권오성 | D53: 원종철 | E53: 반재수 | H53: 49 | I53: 황덕태 | J53: =COUNTIF(($C$4:$E$207),I53) -> 1
A54: 51 | B54: 446 | C54: 정용석 | D54: 조규현 | E54: 김희정 | H54: 50 | J54: =COUNTIF(($C$4:$E$207),I54) -> 0
A55: 52 | B55: 29 | C55: 유양준 | D55: 원종철 | E55: 이준호 | H55: 51 | J55: =COUNTIF(($C$4:$E$207),I55) -> 0
A56: 53 | B56: 109 | C56: 이준호 | D56: 원종철 | E56: 조규현 | H56: 52 | J56: =COUNTIF(($C$4:$E$207),I56) -> 0
...

Sheet Sheet1
F1: 권오성 | H1: 정용석
F2: 권오성 | H2: 권오성
F3: 권오성 | H3: 권오성
F4: 권오성 | H4: 권오성
F5: 권오성 | H5: 권오성
F6: 권오성 | H6: 권오성
F7: 권오성 | H7: 권오성
F8: 권오성 | H8: 권오성
F9: 권오성 | H9: 권오성
C10: 강명구 | F10: 권오성 | H10: 권오성
C11: 권오성 | F11: 권오성 | H11: 권오성
C12: 권오성 | F12: 권오성 | H12: 권오성
C13: 권오성 | F13: 권오성 | H13: 권오성
C14: 권오성 | F14: 권오성 | H14: 권오성
C15: 권오성 | F15: 권오성 | H15: 권오성
C16: 권오성 | F16: 권오성 | H16: 권오성
C17: 권오성 | F17: 권오성 | H17: 권오성
C18: 권오성 | F18: 권오성 | H18: 권오성
C19: 권오성 | F19: 권오성 | H19: 권오성
C20: 권오성 | F20: 권오성 | H20: 권오성
C21: 권오성 | F21: 권오성 | H21: 권오성
... C319: 황덕태 | F319: 이현준 | H319: 이현준
F320: 이현준 | H320: 이현준
F321: 이현준 | H321: 이현준
F322: 이현준 | H322: 이현준
F323: 이현준 | H323: 이현준
F324: 이현준 | H324: 이현준
F325: 이현준 | H325: 이현준
F326: 이현준 | H326: 이현준
F327: 이현준 | H327: 이현준
F328: 이현준 | H328: 이현준
F329: 이현준 | H329: 이현준
F330: 이현준 | H330: 이현준
F331: 이현준 | H331: 임경남
... F445: 최영철 | H445: 조좌영
H446: 진인식
H447: 최영철
H448: 황덕태
H449: 황명수

Sheet 개표집계표B
A1: 2023년 양평동교회 항존직 1차 선거 개표 집계표 - B조
E2: 개표자 : 김영진
A3: 연번 | B3: 일렬번호 | C3: 1 | D3: 2 | E3: 3 | F3: 비고 | H3: 후보합계
A4: 1 | B4: 55 | C4: 권오성 | D4: 정용석 | E4: 조규현 | H4: 연번 | I4: 이름 | J4: 합계
A5: 2 | B5: 135 | C5: 조규현 | D5: 정용석 | E5: 반재수 | H5: 1 | I5: 문동학 | J5: =COUNTIF(($C$4:$E$207),I5) -> 2
A6: 3 | B6: 58 | C6: 반재수 | D6: 백운재 | E6: 김관형 | H6: 2 | I6: 이주이 | J6: =COUNTIF(($C$4:$E$207),I6) -> 2
A7: 4 | B7: 247 | C7: 반재수 | D7: 이현준 | E7: 김희정 | H7: 3 | I7: 이종수 | J7: =COUNTIF(($C$4:$E$207),I7) -> 5
A8: 5 | B8: 248 | C8: 반재수 | D8: 김희정 | E8: 이현준 | H8: 4 | I8: 조근배 | J8: =COUNTIF(($C$4:$E$207),I8) -> 1
A9: 6 | B9: 66 | C9: 김관형 | D9: 원종철 | E9: 반재수 | H9: 5 | I9: 심효섭 | J9: =COUNTIF(($C$4:$E$207),I9) -> 0
A10: 7 | B10: 63 | C10: 권오성 | D10: 정용석 | E10: 백운재 | H10: 6 | I10: 이강우 | J10: =COUNTIF(($C$4:$E$207),I10) -> 3
A11: 8 | B11: 255 | C11: 김희정 | D11: 조규현 | E11: 손성길 | H11: 7 | I11: 반재수 | J11: =COUNTIF(($C$4:$E$207),I11) -> 75
A12: 9 | B12: 259 | C12: 정용석 | D12: 김태성 | E12: 이주이 | H12: 8 | I12: 장태익 | J12: =COUNTIF(($C$4:$E$207),I12) -> 0
A13: 10 | B13: 148 | C13: 권오성 | D13: 반재수 | E13: 원종철 | H13: 9 | I13: 정용석 | J13: =COUNTIF(($C$4:$E$207),I13) -> 70
A14: 11 | B14: 151 | C14: 김희정 | D14: 조규현 | E14: 권오성 | H14: 10 | I14: 유양준 | J14: =COUNTIF(($C$4:$E$207),I14) -> 1
A15: 12 | B15: 150 | C15: 조규현 | D15: 정용석 | E15: 반재수 | H15: 11 | I15: 황명수 | J15: =COUNTIF(($C$4:$E$207),I15) -> 0
A16: 13 | B16: 264 | C16: 문동학 | D16: 김희정 | E16: 김관형 | H16: 12 | I16: 원종철 | J16: =COUNTIF(($C$4:$E$207),I16) -> 34
... A41: 38 | B41: 160 | C41: 반재수 | D41: 정용석 | E41: 이종수 | H41: 37 | I41: 정재호 | J41: =COUNTIF(($C$4:$E$207),I41) -> 0
A42: 39 | B42: 441 | C42: 권오성 | H42: 38 | I42: 배지훈 | J42: =COUNTIF(($C$4:$E$207),I42) -> 0
A43: 40 | B43: 303 | C43: 김관형 | D43: 김태성 | E43: 이재화 | H43: 39 | I43: 정보람 | J43: =COUNTIF(($C$4:$E$207),I43) -> 4
A44: 41 | B44: 339 | C44: 권오성 | D44: 정용석 | E44: 반재수 | H44: 40 | I44: 송학수 | J44: =COUNTIF(($C$4:$E$207),I44) -> 0
A45: 42 | B45: 155 | C45: 조규현 | D45: 이규현 | E45: 정보람 | H45: 41 | I45: 강동일 | J45: =COUNTIF(($C$4:$E$207),I45) -> 0
A46: 43 | B46: 11 | C46: 정용석 | D46: 권오성 | E46: 반재수 | H46: 42 | I46: 손유재 | J46: =COUNTIF(($C$4:$E$207),I46) -> 1
A47: 44 | B47: 106 | C47: 이준호 | D47: 김희정 | E47: 정용석 | H47: 43 | I47: 박재환 | J47: =COUNTIF(($C$4:$E$207),I47) -> 0
A48: 45 | B48: 314 | C48: 이준호 | D48: 조규현 | E48: 김희정 | H48: 44 | I48: 강명구 | J48: =COUNTIF(($C$4:$E$207),I48) -> 0
A49: 46 | B49: 240 | C49: 권오성 | D49: 반재수 | E49: 정용석 | H49: 45 | I49: 김한경 | J49: =COUNTIF(($C$4:$E$207),I49) -> 0
A50: 47 | B50: 125 | C50: 정용석 | D50: 권오성 | E50: 이준호 | H50: 46 | I50: 백선일 | J50: =COUNTIF(($C$4:$E$207),I50) -> 0
A51: 48 | B51: 105 | C51: 반재수 | D51: 정용석 | E51: 권오성 | H51: 47 | I51: 안방선 | J51: =COUNTIF(($C$4:$E$207),I51) -> 3
A52: 49 | B52: 130 | C52: 정보람 | D52: 정용석 | E52: 문용오 | H52: 48 | I52: 박재란 | J52: =COUNTIF(($C$4:$E$207),I52) -> 1
A53: 50 | B53: 332 | C53: 반재수 | D53: 정용석 | E53: 조규현 | H53: 49 | I53: 박세경 | J53: =COUNTIF(($C$4:$E$207),I53) -> 1
A54: 51 | B54: 194 | C54: 정용석 | D54: 김희정 | E54: 이준호 | H54: 50 | I54: 김진상 | J54: =COUNTIF(($C$4:$E$207),I54) -> 1
... A57: 54 | B57: 447 | C57: 조규현 | D57: 정용석 | E57: 김희정 | H57: 53 | I57: 정성훈 | J57: =COUNTIF(($C$4:$E$207),I57) -> 2
A58: 55 | B58: 25 | C58: 권오성 | D58: 백운재 | E58: 원종철 | H58: 54 | J58: =COUNTIF(($C$4:$E$207),I58) -> 0
A59: 56 | B59: 333 | C59: 권오성 | D59: 안방선 | E59: 이종수 | H59: 55 | J59: =COUNTIF(($C$4:$E$207),I59) -> 0
A60: 57 | B60: 234 | C60: 정용석 | D60: 반재수 | E60: 원종철 | H60: 56 | J60: =COUNTIF(($C$4:$E$207),I60) -> 0
A61: 58 | B61: 291 | C61: 조규현 | D61: 김희정 | E61: 반재수 | H61: 57 | J61: =COUNTIF(($C$4:$E$207),I61) -> 0
A62: 59 | B62: 127 | C62: 정용석 | D62: 반재수 | E62: 김희정 | H62: 58 | J62: =COUNTIF(($C$4:$E$207),I62) -> 0
A63: 60 | B63: 123 | C63: 권오성 | D63: 백운재 | E63: 김희정 | H63: 59 | J63: =COUNTIF(($C$4:$E$207),I63) -> 0
A64: 61 | B64: 38 | C64: 반재수 | D64: 백운재 | E64: 이현준 | H64: 60 | J64: =COUNTIF(($C$4:$E$207),I64) -> 0
A65: 62 | B65: 227 | C65: 권오성 | H65: 61 | J65: =COUNTIF(($C$4:$E$207),I65) -> 0
A66: 63 | B66: 20 | C66: 이준호 | D66: 조규현 | E66: 김희정 | I66: 무효표 | J66: =COUNTIF(($C$4:$E$153),"") -> 5
...

Sheet 개표집계표C
A1: 2023년 양평동교회 항존직 1차 선거 개표 집계표 - C조
E2: 개표자 : 백철우
A3: 연번 | B3: 일렬번호 | C3: 1 | D3: 2 | E3: 3 | F3: 비고 | H3: 후보합계
A4: 1 | B4: 71 | C4: 정용석 | D4: 조규현 | E4: 반재수 | H4: 연번 | I4: 이름 | J4: 합계
A5: 2 | B5: 60 | C5: 반재수 | D5: 권오성 | E5: 원종철 | H5: 1 | I5: 문동학 | J5: =COUNTIF(($C$4:$E$207),I5) -> 9
A6: 3 | B6: 405 | C6: 권오성 | D6: 반재수 | E6: 이준호 | H6: 2 | I6: 이주이 | J6: =COUNTIF(($C$4:$E$207),I6) -> 1
A7: 4 | B7: 440 | C7: 조규현 | D7: 김희정 | E7: 손유재 | H7: 3 | I7: 이종수 | J7: =COUNTIF(($C$4:$E$207),I7) -> 12
A8: 5 | B8: 407 | C8: 정용석 | D8: 반재수 | E8: 이준호 | H8: 4 | I8: 조근배 | J8: =COUNTIF(($C$4:$E$207),I8) -> 2
A9: 6 | B9: 293 | C9: 안방선 | D9: 정용석 | E9: 권오성 | H9: 5 | I9: 심효섭 | J9: =COUNTIF(($C$4:$E$207),I9) -> 2
A10: 7 | B10: 19 | C10: 권오성 | D10: 원종철 | E10: 이주이 | H10: 6 | I10: 이강우 | J10: =COUNTIF(($C$4:$E$207),I10) -> 4
A11: 8 | B11: 140 | C11: 반재수 | D11: 권오성 | E11: 정용석 | H11: 7 | I11: 반재수 | J11: =COUNTIF(($C$4:$E$207),I11) -> 70
A12: 9 | B12: 197 | C12: 이규현 | D12: 권오성 | E12: 원종철 | H12: 8 | I12: 장태익 | J12: =COUNTIF(($C$4:$E$207),I12) -> 3
A13: 10 | B13: 454 | C13: 이준호 | D13: 반재수 | E13: 정용석 | H13: 9 | I13: 정용석 | J13: =COUNTIF(($C$4:$E$207),I13) -> 75
A14: 11 | B14: 318 | C14: 반재수 | D14: 권오성 | E14: 조규현 | H14: 10 | I14: 유양준 | J14: =COUNTIF(($C$4:$E$207),I14) -> 0
A15: 12 | B15: 340 | C15: 정용석 | D15: 이현준 | E15: 반재수 | H15: 11 | I15: 황명수 | J15: =COUNTIF(($C$4:$E$207),I15) -> 1
A16: 13 | B16: 153 | C16: 정보람 | D16: 김관형 | E16: 이규현 | H16: 12 | I16: 원종철 | J16: =COUNTIF(($C$4:$E$207),I16) -> 27
... A55: 52 | B55: 408 | C55: 권오성 | D55: 조규현 | E55: 정용석 | H55: 51 | I55: 황덕태 | J55: =COUNTIF(($C$4:$E$207),I55) -> 1
A56: 53 | B56: 12 | C56: 안방선 | D56: 김희정 | E56: 원종철 | H56: 52 | J56: =COUNTIF(($C$4:$E$207),I56) -> 0
A57: 54 | B57: 328 | C57: 반재수 | D57: 김남영 | E57: 이종수 | H57: 53 | J57: =COUNTIF(($C$4:$E$207),I57) -> 0
A58: 55 | B58: 215 | C58: 정용석 | D58: 백운재 | E58: 김희정 | H58: 54 | J58: =COUNTIF(($C$4:$E$207),I58) -> 0
A59: 56 | B59: 204 | C59: 권오성 | D59: 반재수 | E59: 이현준 | H59: 55 | J59: =COUNTIF(($C$4:$E$207),I59) -> 0
A60: 57 | B60: 205 | C60: 이현준 | D60: 김태성 | E60: 권오성 | H60: 56 | J60: =COUNTIF(($C$4:$E$207),I60) -> 0
A61: 58 | B61: 203 | C61: 조규현 | D61: 원종철 | E61: 문용오 | H61: 57 | J61: =COUNTIF(($C$4:$E$207),I61) -> 0
A62: 59 | B62: 6 | C62: 정용석 | D62: 반재수 | E62: 문용오 | H62: 58 | J62: =COUNTIF(($C$4:$E$207),I62) -> 0
A63: 60 | B63: 131 | C63: 이현준 | D63: 정용석 | E63: 권오성 | H63: 59 | J63: =COUNTIF(($C$4:$E$207),I63) -> 0
A64: 61 | B64: 212 | C64: 정용석 | D64: 임경남 | E64: 권오성 | H64: 60 | J64: =COUNTIF(($C$4:$E$207),I64) -> 0
A65: 62 | B65: 252 | C65: 이강우 | D65: 반재수 | E65: 정용석 | H65: 61 | J65: =COUNTIF(($C$4:$E$207),I65) -> 0
A66: 63 | B66: 196 | C66: 권오성 | D66: 이준호 | E66: 반재수 | I66: 무효표 | J66: =COUNTIF(($C$4:$E$154),"") -> 4
A67: 64 | B67: 77 | C67: 문동학 | D67: 정용석 | E67: 조규현 | I67: 합계표 | J67: =SUM(J5:J66)/3 -> 151
A68: 65 | B68: 448 | C68: 정용석 | D68: 조규현
A69: 66 | B69: 275 | C69: 권오성 | D69: 정용석 | E69: 김남영
A70: 67 | B70: 4 | C70: 반재수 | D70: 권오성 | E70: 이현준
A71: 68 | B71: 346 | C71: 권오성 | D71: 백운재 | E71: 원종철
A72: 69 | B72: 202 | C72: 반재수 | D72: 김태성 | E72: 조규현
A73: 70 | B73: 214 | C73: 권오성 | D73: 이준호 | E73: 반재수
A74: 71 | B74: 179 | C74: 이준호 | D74: 이현준 | E74: 권오성
A75: 72 | B75: 413 | C75: 권오성 | D75: 이준호 | E75: 문용오
A76: 73 | B76: 2 | C76: 권오성 | D76: 정용석 | E76: 반재수
A77: 74 | B77: 436 | C77: 반재수 | D77: 김관형 | E77: 원종철
A78: 75 | B78: 189 | C78: 이규현 | D78: 권오성 | E78: 정용석
...
